{
 "cells": [
  {
   "cell_type": "code",
   "execution_count": 1,
   "id": "d3d95a31",
   "metadata": {},
   "outputs": [],
   "source": [
    "from keras.models import load_model\n",
    "from sklearn.metrics import confusion_matrix, accuracy_score, classification_report\n",
    "import numpy as np"
   ]
  },
  {
   "cell_type": "code",
   "execution_count": 3,
   "id": "7a8efa8e",
   "metadata": {},
   "outputs": [
    {
     "name": "stderr",
     "output_type": "stream",
     "text": [
      "WARNING:absl:Skipping variable loading for optimizer 'Adam', because it has 21 variables whereas the saved optimizer has 1 variables. \n"
     ]
    }
   ],
   "source": [
    "# load test data and trained model\n",
    "X_test = np.loadtxt(\"input_test.csv\",delimiter = ',')\n",
    "Y_test = np.loadtxt(\"labels_test.csv\",delimiter = ',')\n",
    "loaded_model = load_model(\"trained_model.keras\")"
   ]
  },
  {
   "cell_type": "code",
   "execution_count": 4,
   "id": "dd62e485",
   "metadata": {},
   "outputs": [
    {
     "ename": "ValueError",
     "evalue": "in user code:\n\n    File \"C:\\Users\\Mustafa\\anaconda3\\Lib\\site-packages\\keras\\src\\engine\\training.py\", line 2416, in predict_function  *\n        return step_function(self, iterator)\n    File \"C:\\Users\\Mustafa\\anaconda3\\Lib\\site-packages\\keras\\src\\engine\\training.py\", line 2401, in step_function  **\n        outputs = model.distribute_strategy.run(run_step, args=(data,))\n    File \"C:\\Users\\Mustafa\\anaconda3\\Lib\\site-packages\\keras\\src\\engine\\training.py\", line 2389, in run_step  **\n        outputs = model.predict_step(data)\n    File \"C:\\Users\\Mustafa\\anaconda3\\Lib\\site-packages\\keras\\src\\engine\\training.py\", line 2357, in predict_step\n        return self(x, training=False)\n    File \"C:\\Users\\Mustafa\\anaconda3\\Lib\\site-packages\\keras\\src\\utils\\traceback_utils.py\", line 70, in error_handler\n        raise e.with_traceback(filtered_tb) from None\n    File \"C:\\Users\\Mustafa\\anaconda3\\Lib\\site-packages\\keras\\src\\engine\\input_spec.py\", line 298, in assert_input_compatibility\n        raise ValueError(\n\n    ValueError: Input 0 of layer \"sequential_2\" is incompatible with the layer: expected shape=(None, 100, 100, 3), found shape=(None, 30000)\n",
     "output_type": "error",
     "traceback": [
      "\u001b[1;31m---------------------------------------------------------------------------\u001b[0m",
      "\u001b[1;31mValueError\u001b[0m                                Traceback (most recent call last)",
      "Cell \u001b[1;32mIn[4], line 1\u001b[0m\n\u001b[1;32m----> 1\u001b[0m Y_pred \u001b[38;5;241m=\u001b[39m loaded_model\u001b[38;5;241m.\u001b[39mpredict(X_test)\n\u001b[0;32m      2\u001b[0m Y_pred_classes \u001b[38;5;241m=\u001b[39m (Y_pred \u001b[38;5;241m>\u001b[39m \u001b[38;5;241m0.5\u001b[39m)\u001b[38;5;241m.\u001b[39mastype(\u001b[38;5;124m'\u001b[39m\u001b[38;5;124mint\u001b[39m\u001b[38;5;124m'\u001b[39m)\n\u001b[0;32m      3\u001b[0m conf_matrix \u001b[38;5;241m=\u001b[39m confusion_matrix(Y_test, Y_pred_classes)\n",
      "File \u001b[1;32m~\\anaconda3\\Lib\\site-packages\\keras\\src\\utils\\traceback_utils.py:70\u001b[0m, in \u001b[0;36mfilter_traceback.<locals>.error_handler\u001b[1;34m(*args, **kwargs)\u001b[0m\n\u001b[0;32m     67\u001b[0m     filtered_tb \u001b[38;5;241m=\u001b[39m _process_traceback_frames(e\u001b[38;5;241m.\u001b[39m__traceback__)\n\u001b[0;32m     68\u001b[0m     \u001b[38;5;66;03m# To get the full stack trace, call:\u001b[39;00m\n\u001b[0;32m     69\u001b[0m     \u001b[38;5;66;03m# `tf.debugging.disable_traceback_filtering()`\u001b[39;00m\n\u001b[1;32m---> 70\u001b[0m     \u001b[38;5;28;01mraise\u001b[39;00m e\u001b[38;5;241m.\u001b[39mwith_traceback(filtered_tb) \u001b[38;5;28;01mfrom\u001b[39;00m \u001b[38;5;28;01mNone\u001b[39;00m\n\u001b[0;32m     71\u001b[0m \u001b[38;5;28;01mfinally\u001b[39;00m:\n\u001b[0;32m     72\u001b[0m     \u001b[38;5;28;01mdel\u001b[39;00m filtered_tb\n",
      "File \u001b[1;32m~\\AppData\\Local\\Temp\\__autograph_generated_filej30d9mpi.py:15\u001b[0m, in \u001b[0;36mouter_factory.<locals>.inner_factory.<locals>.tf__predict_function\u001b[1;34m(iterator)\u001b[0m\n\u001b[0;32m     13\u001b[0m \u001b[38;5;28;01mtry\u001b[39;00m:\n\u001b[0;32m     14\u001b[0m     do_return \u001b[38;5;241m=\u001b[39m \u001b[38;5;28;01mTrue\u001b[39;00m\n\u001b[1;32m---> 15\u001b[0m     retval_ \u001b[38;5;241m=\u001b[39m ag__\u001b[38;5;241m.\u001b[39mconverted_call(ag__\u001b[38;5;241m.\u001b[39mld(step_function), (ag__\u001b[38;5;241m.\u001b[39mld(\u001b[38;5;28mself\u001b[39m), ag__\u001b[38;5;241m.\u001b[39mld(iterator)), \u001b[38;5;28;01mNone\u001b[39;00m, fscope)\n\u001b[0;32m     16\u001b[0m \u001b[38;5;28;01mexcept\u001b[39;00m:\n\u001b[0;32m     17\u001b[0m     do_return \u001b[38;5;241m=\u001b[39m \u001b[38;5;28;01mFalse\u001b[39;00m\n",
      "\u001b[1;31mValueError\u001b[0m: in user code:\n\n    File \"C:\\Users\\Mustafa\\anaconda3\\Lib\\site-packages\\keras\\src\\engine\\training.py\", line 2416, in predict_function  *\n        return step_function(self, iterator)\n    File \"C:\\Users\\Mustafa\\anaconda3\\Lib\\site-packages\\keras\\src\\engine\\training.py\", line 2401, in step_function  **\n        outputs = model.distribute_strategy.run(run_step, args=(data,))\n    File \"C:\\Users\\Mustafa\\anaconda3\\Lib\\site-packages\\keras\\src\\engine\\training.py\", line 2389, in run_step  **\n        outputs = model.predict_step(data)\n    File \"C:\\Users\\Mustafa\\anaconda3\\Lib\\site-packages\\keras\\src\\engine\\training.py\", line 2357, in predict_step\n        return self(x, training=False)\n    File \"C:\\Users\\Mustafa\\anaconda3\\Lib\\site-packages\\keras\\src\\utils\\traceback_utils.py\", line 70, in error_handler\n        raise e.with_traceback(filtered_tb) from None\n    File \"C:\\Users\\Mustafa\\anaconda3\\Lib\\site-packages\\keras\\src\\engine\\input_spec.py\", line 298, in assert_input_compatibility\n        raise ValueError(\n\n    ValueError: Input 0 of layer \"sequential_2\" is incompatible with the layer: expected shape=(None, 100, 100, 3), found shape=(None, 30000)\n"
     ]
    }
   ],
   "source": [
    "Y_pred = loaded_model.predict(X_test)\n",
    "Y_pred_classes = (Y_pred > 0.5).astype('int')\n",
    "conf_matrix = confusion_matrix(Y_test, Y_pred_classes)\n",
    "accuracy = accuracy_score(Y_test, Y_pred_classes)\n",
    "classification_report_result = classification_report(Y_test, Y_pred_classes)\n",
    "\n",
    "# Sonuçları yazdırın\n",
    "print(\"Accuracy on Test Set: {:.2f}%\".format(accuracy * 100))\n",
    "print(\"Confusion Matrix:\\n\", conf_matrix)\n",
    "print(\"Classification Report:\\n\", classification_report_result)"
   ]
  }
 ],
 "metadata": {
  "kernelspec": {
   "display_name": "Python 3 (ipykernel)",
   "language": "python",
   "name": "python3"
  },
  "language_info": {
   "codemirror_mode": {
    "name": "ipython",
    "version": 3
   },
   "file_extension": ".py",
   "mimetype": "text/x-python",
   "name": "python",
   "nbconvert_exporter": "python",
   "pygments_lexer": "ipython3",
   "version": "3.11.5"
  }
 },
 "nbformat": 4,
 "nbformat_minor": 5
}
